翔实的失败报告
===================================================================================
示例中的测试尝试去创建一个宽度为2的元素，并断言产出的元素的宽度的确为2。如果这个断言失败，**失败报
告** 就会包括 **文件名** 和该断言 **所在的行号**，以及一条 **翔实的错误消息**：
```scala
import org.scalatest.FunSuite
import Element.elem

class ElementSuite extends FunSuite {
  test("elem result should have passed width"){
    val ele = elem('x', 2, 3)
    assert(ele.width == 3)
  }
}
```
失败报告：
```
2 did not equal 3
ScalaTestFailureLocation: ElementSuite at (ElementSuite.scala:7)
Expected :3
Actual   :2

org.scalatest.exceptions.TestFailedException: 2 did not equal 3
	at org.scalatest.Assertions.newAssertionFailedException(Assertions.scala:530)
    ......
```
为了在断言失败时提供描述性的错误消息，**ScalaTest会在编译时分析每次传入assert调用的表达式**。

**ScalaTest的assert方法并不在错误消息中区分实际和预期的结果，它们仅仅是提示我们左侧的操作元跟右侧的
操作元不相等。如果你想要强调实际和预期的差别，可以换用ScalaTest的assertResult方法**，示例：
```scala
import org.scalatest.FunSuite
import Element.elem

class ElementSuite extends FunSuite {
  test("elem result should have passed width"){
    val ele = elem('x', 2, 3)
    assertResult(3){
      ele.width
    }
  }
}
```
失败报告：
```
Expected 3, but got 2
ScalaTestFailureLocation: ElementSuite at (ElementSuite.scala:7)
org.scalatest.exceptions.TestFailedException: Expected 3, but got 2
	at org.scalatest.Assertions.newAssertionFailedException(Assertions.scala:530)
    ......
```
通过这个表达式，你表明了你预期花括号中的代码的执行结是3。如果花括号中的代码执行结果是2，你将会在失
败报告中看到“Expected 3, but got 2”这样的消息。

**如果你想要检查某个方法抛出某个预期的异常，可以用ScalaTest的assertThrows方法**，就像这样：
```scala
import org.scalatest.FunSuite
import Element.elem

class ElementSuite extends FunSuite {
  test("elem result should have passed width") {
    assertThrows[IllegalArgumentException] {
      elem('x', -2, 3)
    }
  }
}
```
失败报告：
```
Expected exception java.lang.IllegalArgumentException to be thrown, but java.lang.NegativeArraySizeException was thrown
ScalaTestFailureLocation: ElementSuite at (ElementSuite.scala:6)
org.scalatest.exceptions.TestFailedException: Expected exception java.lang.IllegalArgumentException to be thrown, but java.lang.NegativeArraySizeException was thrown
	at org.scalatest.Assertions.newAssertionFailedException(Assertions.scala:530)
    ......
```
**如果花括号中的代码抛出了不同于预期的异常，或者并没有抛出异常，assertThrows将以TestFailedException
异常终止。而如果代码以传入的异常类的实例异常终止（即代码抛出了预期的异常），assertThrows将正常返回**。

**如果你想要进一步检视预期的异常，可以使用intercept而不是assertThrows**。intercept方法跟assertThrows
的运行机制相同，**不过当异常被抛出时，intercept将返回这个异常**：
```scala
import org.scalatest.FunSuite

class ElementSuite extends FunSuite {
  test("elem result should have passed width") {
    val caught = intercept[ArithmeticException] {
      1/0
    }
    assert(caught.getMessage == "/ by zero")
  }
}
```
简而言之，ScalaTest的断言会尽其所能提供有助于我们诊断和修复代码问题的失败消息。

